Workbook
Name _Ref138870690: 'KrXe-handCalculation-BB'!$C$47

Sheet analytics
A1: reaction | B1: Batch reaction | C1: half-life (second) | D1: rate k (s-1) | E1: log rate constant | F1: molecular mass | G1: 4He yield per reaction | H1: mass of mineral (mole) | I1: density of mineral (g/ml) | J1: mineral volume fraction | K1: rate mol/L bulk / day | L1: 4He yield (mole per second) | M1: 4He yield (mole per year)
A2: 238U-yield-8-4He | B2: Ref: Ballentine2002 | C2: =365*86400*4468000000 -> 1.4090285e+17 | D2: =LN(2)/C2 -> 4.919327e-18 | E2: =LOG10(D2) -> -17.308094 | F2: 238 | G2: 8 | H2: =1/F2 -> 0.0042016807 | I2: 19.1 | J2: =H2*F2/I2/1000000 -> 5.2356021e-08 | K2: =D2*86400*H2/1000 -> 1.7858397e-18 | L2: =D2*H2*G2 -> 1.6535553e-19 | M2: =L2*86400*365 -> 5.2146519e-12
A3: 235U-yield-7-4He | C3: =365*86400*703800000 -> 2.2195037e+16 | D3: =LN(2)/C3 -> 3.1229828e-17 | E3: =LOG10(D3) -> -16.50543 | F3: 235 | G3: 7 | H3: =1/F3 -> 0.0042553191 | I3: 19.1 | J3: =H3*F3/I3/1000000 -> 5.2356021e-08 | K3: =D3*86400*H3/1000 -> 1.1481945e-17 | L3: =D3*H3*G3 -> 9.3025019e-19 | M3: =L3*86400*365 -> 2.933637e-11
A4: 232Th-yield-6-4He | C4: =365*86400*14000000000 -> 4.41504e+17 | D4: =LN(2)/C4 -> 1.5699681e-18 | E4: =LOG10(D4) -> -17.804109 | F4: 232 | G4: 6 | H4: =1/F4 -> 0.0043103448 | I4: 11.7 | J4: =H4*F4/I4/1000000 -> 8.5470085e-08 | K4: =D4*86400*H4/1000 -> 5.8467776e-19 | L4: =D4*H4*G4 -> 4.0602622e-20 | M4: =L4*86400*365 -> 1.2804443e-12
L5: Total 4He yield per year | M5: =SUM(M2:M4) -> 3.5831466e-11
J6: =H2*F2 -> 1
B8: 1D diffusion | C8: G (mol per year) | D8: =M2 -> 5.2146519e-12 | E8: =M2 -> 5.2146519e-12 | F8: =M2 -> 5.2146519e-12 | G8: =M2 -> 5.2146519e-12 | H8: =M2 -> 5.2146519e-12
B9: Ref: Andrews1989 | C9: D (m^2 per year) | D9: 1e-07 | E9: 5e-07 | F9: 1e-06 | G9: 1e-06 | H9: 1e-06
C10: T (year) | D10: 100000000 | E10: 100000000 | F10: 100000000 | G10: 50000000 | H10: 10000000
B11: Analytical solution | C11: Z (depth m) | D11: C (mol m^-3) | E11: C (mol m^-3)
C12: 0 | D12: =D$8*D$10*(1-EXP(-2*$C12/SQRT(PI()*D$9*D$10))) -> 0 | E12: =E$8*E$10*(1-EXP(-2*$C12/SQRT(PI()*E$9*E$10))) -> 0 | F12: =F$8*F$10*(1-EXP(-2*$C12/SQRT(PI()*F$9*F$10))) -> 0 | G12: =G$8*G$10*(1-EXP(-2*$C12/SQRT(PI()*G$9*G$10))) -> 0 | H12: =H$8*H$10*(1-EXP(-2*$C12/SQRT(PI()*H$9*H$10))) -> 0
C13: 0.1 | D13: =D$8*D$10*(1-EXP(-2*$C13/SQRT(PI()*D$9*D$10))) -> 1.8279111e-05 | E13: =E$8*E$10*(1-EXP(-2*$C13/SQRT(PI()*E$9*E$10))) -> 8.2553373e-06 | F13: =F$8*F$10*(1-EXP(-2*$C13/SQRT(PI()*F$9*F$10))) -> 5.8510316e-06 | G13: =G$8*G$10*(1-EXP(-2*$C13/SQRT(PI()*G$9*G$10))) -> 4.1276687e-06 | H13: =H$8*H$10*(1-EXP(-2*$C13/SQRT(PI()*H$9*H$10))) -> 1.8279111e-06
C14: 0.2 | D14: =D$8*D$10*(1-EXP(-2*$C14/SQRT(PI()*D$9*D$10))) -> 3.5917478e-05 | E14: =E$8*E$10*(1-EXP(-2*$C14/SQRT(PI()*E$9*E$10))) -> 1.6379984e-05 | F14: =F$8*F$10*(1-EXP(-2*$C14/SQRT(PI()*F$9*F$10))) -> 1.1636413e-05 | G14: =G$8*G$10*(1-EXP(-2*$C14/SQRT(PI()*G$9*G$10))) -> 8.189992e-06 | H14: =H$8*H$10*(1-EXP(-2*$C14/SQRT(PI()*H$9*H$10))) -> 3.5917478e-06
C15: 0.3 | D15: =D$8*D$10*(1-EXP(-2*$C15/SQRT(PI()*D$9*D$10))) -> 5.293756e-05 | E15: =E$8*E$10*(1-EXP(-2*$C15/SQRT(PI()*E$9*E$10))) -> 2.4376009e-05 | F15: =F$8*F$10*(1-EXP(-2*$C15/SQRT(PI()*F$9*F$10))) -> 1.7356879e-05 | G15: =G$8*G$10*(1-EXP(-2*$C15/SQRT(PI()*G$9*G$10))) -> 1.2188005e-05 | H15: =H$8*H$10*(1-EXP(-2*$C15/SQRT(PI()*H$9*H$10))) -> 5.293756e-06
C16: 0.4 | D16: =D$8*D$10*(1-EXP(-2*$C16/SQRT(PI()*D$9*D$10))) -> 6.9361032e-05 | E16: =E$8*E$10*(1-EXP(-2*$C16/SQRT(PI()*E$9*E$10))) -> 3.2245449e-05 | F16: =F$8*F$10*(1-EXP(-2*$C16/SQRT(PI()*F$9*F$10))) -> 2.301316e-05 | G16: =G$8*G$10*(1-EXP(-2*$C16/SQRT(PI()*G$9*G$10))) -> 1.6122724e-05 | H16: =H$8*H$10*(1-EXP(-2*$C16/SQRT(PI()*H$9*H$10))) -> 6.9361032e-06
C17: 0.5 | D17: =D$8*D$10*(1-EXP(-2*$C17/SQRT(PI()*D$9*D$10))) -> 8.5208805e-05 | E17: =E$8*E$10*(1-EXP(-2*$C17/SQRT(PI()*E$9*E$10))) -> 3.9990307e-05 | F17: =F$8*F$10*(1-EXP(-2*$C17/SQRT(PI()*F$9*F$10))) -> 2.8605976e-05 | G17: =G$8*G$10*(1-EXP(-2*$C17/SQRT(PI()*G$9*G$10))) -> 1.9995154e-05 | H17: =H$8*H$10*(1-EXP(-2*$C17/SQRT(PI()*H$9*H$10))) -> 8.5208805e-06
C18: 0.6 | D18: =D$8*D$10*(1-EXP(-2*$C18/SQRT(PI()*D$9*D$10))) -> 0.00010050106 | E18: =E$8*E$10*(1-EXP(-2*$C18/SQRT(PI()*E$9*E$10))) -> 4.7612556e-05 | F18: =F$8*F$10*(1-EXP(-2*$C18/SQRT(PI()*F$9*F$10))) -> 3.4136038e-05 | G18: =G$8*G$10*(1-EXP(-2*$C18/SQRT(PI()*G$9*G$10))) -> 2.3806278e-05 | H18: =H$8*H$10*(1-EXP(-2*$C18/SQRT(PI()*H$9*H$10))) -> 1.0050106e-05
C19: 0.7 | D19: =D$8*D$10*(1-EXP(-2*$C19/SQRT(PI()*D$9*D$10))) -> 0.00011525727 | E19: =E$8*E$10*(1-EXP(-2*$C19/SQRT(PI()*E$9*E$10))) -> 5.5114137e-05 | F19: =F$8*F$10*(1-EXP(-2*$C19/SQRT(PI()*F$9*F$10))) -> 3.9604051e-05 | G19: =G$8*G$10*(1-EXP(-2*$C19/SQRT(PI()*G$9*G$10))) -> 2.7557069e-05 | H19: =H$8*H$10*(1-EXP(-2*$C19/SQRT(PI()*H$9*H$10))) -> 1.1525727e-05
C20: 0.8 | D20: =D$8*D$10*(1-EXP(-2*$C20/SQRT(PI()*D$9*D$10))) -> 0.00012949623 | E20: =E$8*E$10*(1-EXP(-2*$C20/SQRT(PI()*E$9*E$10))) -> 6.249696e-05 | F20: =F$8*F$10*(1-EXP(-2*$C20/SQRT(PI()*F$9*F$10))) -> 4.501071e-05 | G20: =G$8*G$10*(1-EXP(-2*$C20/SQRT(PI()*G$9*G$10))) -> 3.124848e-05 | H20: =H$8*H$10*(1-EXP(-2*$C20/SQRT(PI()*H$9*H$10))) -> 1.2949623e-05
C21: 0.9 | D21: =D$8*D$10*(1-EXP(-2*$C21/SQRT(PI()*D$9*D$10))) -> 0.00014323606 | E21: =E$8*E$10*(1-EXP(-2*$C21/SQRT(PI()*E$9*E$10))) -> 6.9762906e-05 | F21: =F$8*F$10*(1-EXP(-2*$C21/SQRT(PI()*F$9*F$10))) -> 5.0356705e-05 | G21: =G$8*G$10*(1-EXP(-2*$C21/SQRT(PI()*G$9*G$10))) -> 3.4881453e-05 | H21: =H$8*H$10*(1-EXP(-2*$C21/SQRT(PI()*H$9*H$10))) -> 1.4323606e-05
C22: 1 | D22: =D$8*D$10*(1-EXP(-2*$C22/SQRT(PI()*D$9*D$10))) -> 0.00015649426 | E22: =E$8*E$10*(1-EXP(-2*$C22/SQRT(PI()*E$9*E$10))) -> 7.6913823e-05 | F22: =F$8*F$10*(1-EXP(-2*$C22/SQRT(PI()*F$9*F$10))) -> 5.5642716e-05 | G22: =G$8*G$10*(1-EXP(-2*$C22/SQRT(PI()*G$9*G$10))) -> 3.8456912e-05 | H22: =H$8*H$10*(1-EXP(-2*$C22/SQRT(PI()*H$9*H$10))) -> 1.5649426e-05
C23: 1.1 | D23: =D$8*D$10*(1-EXP(-2*$C23/SQRT(PI()*D$9*D$10))) -> 0.00016928772 | E23: =E$8*E$10*(1-EXP(-2*$C23/SQRT(PI()*E$9*E$10))) -> 8.3951535e-05 | F23: =F$8*F$10*(1-EXP(-2*$C23/SQRT(PI()*F$9*F$10))) -> 6.0869416e-05 | G23: =G$8*G$10*(1-EXP(-2*$C23/SQRT(PI()*G$9*G$10))) -> 4.1975767e-05 | H23: =H$8*H$10*(1-EXP(-2*$C23/SQRT(PI()*H$9*H$10))) -> 1.6928772e-05
... C28: 1.6 | D28: =D$8*D$10*(1-EXP(-2*$C28/SQRT(PI()*D$9*D$10))) -> 0.00022683446 | E28: =E$8*E$10*(1-EXP(-2*$C28/SQRT(PI()*E$9*E$10))) -> 0.00011750374 | F28: =F$8*F$10*(1-EXP(-2*$C28/SQRT(PI()*F$9*F$10))) -> 8.6136283e-05 | G28: =G$8*G$10*(1-EXP(-2*$C28/SQRT(PI()*G$9*G$10))) -> 5.8751868e-05 | H28: =H$8*H$10*(1-EXP(-2*$C28/SQRT(PI()*H$9*H$10))) -> 2.2683446e-05
C29: 1.7 | D29: =D$8*D$10*(1-EXP(-2*$C29/SQRT(PI()*D$9*D$10))) -> 0.00023716226 | E29: =E$8*E$10*(1-EXP(-2*$C29/SQRT(PI()*E$9*E$10))) -> 0.00012389887 | F29: =F$8*F$10*(1-EXP(-2*$C29/SQRT(PI()*F$9*F$10))) -> 9.1020834e-05 | G29: =G$8*G$10*(1-EXP(-2*$C29/SQRT(PI()*G$9*G$10))) -> 6.1949434e-05 | H29: =H$8*H$10*(1-EXP(-2*$C29/SQRT(PI()*H$9*H$10))) -> 2.3716226e-05 | J29: 1g U-238 in 1 dm3 solids = ?ppm
C30: 1.8 | D30: =D$8*D$10*(1-EXP(-2*$C30/SQRT(PI()*D$9*D$10))) -> 0.00024712804 | E30: =E$8*E$10*(1-EXP(-2*$C30/SQRT(PI()*E$9*E$10))) -> 0.00013019276 | F30: =F$8*F$10*(1-EXP(-2*$C30/SQRT(PI()*F$9*F$10))) -> 9.5850578e-05 | G30: =G$8*G$10*(1-EXP(-2*$C30/SQRT(PI()*G$9*G$10))) -> 6.5096378e-05 | H30: =H$8*H$10*(1-EXP(-2*$C30/SQRT(PI()*H$9*H$10))) -> 2.4712804e-05 | J30: =1/19.1 -> 0.052356021
C31: 1.9 | D31: =D$8*D$10*(1-EXP(-2*$C31/SQRT(PI()*D$9*D$10))) -> 0.00025674448 | E31: =E$8*E$10*(1-EXP(-2*$C31/SQRT(PI()*E$9*E$10))) -> 0.00013638701 | F31: =F$8*F$10*(1-EXP(-2*$C31/SQRT(PI()*F$9*F$10))) -> 0.00010062613 | G31: =G$8*G$10*(1-EXP(-2*$C31/SQRT(PI()*G$9*G$10))) -> 6.8193504e-05 | H31: =H$8*H$10*(1-EXP(-2*$C31/SQRT(PI()*H$9*H$10))) -> 2.5674448e-05
C32: 2 | D32: =D$8*D$10*(1-EXP(-2*$C32/SQRT(PI()*D$9*D$10))) -> 0.00026602383 | E32: =E$8*E$10*(1-EXP(-2*$C32/SQRT(PI()*E$9*E$10))) -> 0.0001424832 | F32: =F$8*F$10*(1-EXP(-2*$C32/SQRT(PI()*F$9*F$10))) -> 0.0001053481 | G32: =G$8*G$10*(1-EXP(-2*$C32/SQRT(PI()*G$9*G$10))) -> 7.1241598e-05 | H32: =H$8*H$10*(1-EXP(-2*$C32/SQRT(PI()*H$9*H$10))) -> 2.6602383e-05
C33: 2.1 | D33: =D$8*D$10*(1-EXP(-2*$C33/SQRT(PI()*D$9*D$10))) -> 0.00027497791 | E33: =E$8*E$10*(1-EXP(-2*$C33/SQRT(PI()*E$9*E$10))) -> 0.00014848288 | F33: =F$8*F$10*(1-EXP(-2*$C33/SQRT(PI()*F$9*F$10))) -> 0.00011001709 | G33: =G$8*G$10*(1-EXP(-2*$C33/SQRT(PI()*G$9*G$10))) -> 7.4241438e-05 | H33: =H$8*H$10*(1-EXP(-2*$C33/SQRT(PI()*H$9*H$10))) -> 2.7497791e-05
C34: 2.2 | D34: =D$8*D$10*(1-EXP(-2*$C34/SQRT(PI()*D$9*D$10))) -> 0.00028361812 | E34: =E$8*E$10*(1-EXP(-2*$C34/SQRT(PI()*E$9*E$10))) -> 0.00015438757 | F34: =F$8*F$10*(1-EXP(-2*$C34/SQRT(PI()*F$9*F$10))) -> 0.00011463369 | G34: =G$8*G$10*(1-EXP(-2*$C34/SQRT(PI()*G$9*G$10))) -> 7.7193787e-05 | H34: =H$8*H$10*(1-EXP(-2*$C34/SQRT(PI()*H$9*H$10))) -> 2.8361812e-05
C35: 2.3 | D35: =D$8*D$10*(1-EXP(-2*$C35/SQRT(PI()*D$9*D$10))) -> 0.00029195546 | E35: =E$8*E$10*(1-EXP(-2*$C35/SQRT(PI()*E$9*E$10))) -> 0.0001601988 | F35: =F$8*F$10*(1-EXP(-2*$C35/SQRT(PI()*F$9*F$10))) -> 0.00011919849 | G35: =G$8*G$10*(1-EXP(-2*$C35/SQRT(PI()*G$9*G$10))) -> 8.0099398e-05 | H35: =H$8*H$10*(1-EXP(-2*$C35/SQRT(PI()*H$9*H$10))) -> 2.9195546e-05
C36: 2.4 | D36: =D$8*D$10*(1-EXP(-2*$C36/SQRT(PI()*D$9*D$10))) -> 0.00030000055 | E36: =E$8*E$10*(1-EXP(-2*$C36/SQRT(PI()*E$9*E$10))) -> 0.00016591802 | F36: =F$8*F$10*(1-EXP(-2*$C36/SQRT(PI()*F$9*F$10))) -> 0.00012371207 | G36: =G$8*G$10*(1-EXP(-2*$C36/SQRT(PI()*G$9*G$10))) -> 8.295901e-05 | H36: =H$8*H$10*(1-EXP(-2*$C36/SQRT(PI()*H$9*H$10))) -> 3.0000055e-05
C37: 2.5 | D37: =D$8*D$10*(1-EXP(-2*$C37/SQRT(PI()*D$9*D$10))) -> 0.00030776363 | E37: =E$8*E$10*(1-EXP(-2*$C37/SQRT(PI()*E$9*E$10))) -> 0.0001715467 | F37: =F$8*F$10*(1-EXP(-2*$C37/SQRT(PI()*F$9*F$10))) -> 0.000128175 | G37: =G$8*G$10*(1-EXP(-2*$C37/SQRT(PI()*G$9*G$10))) -> 8.5773351e-05 | H37: =H$8*H$10*(1-EXP(-2*$C37/SQRT(PI()*H$9*H$10))) -> 3.0776363e-05
C38: 2.6 | D38: =D$8*D$10*(1-EXP(-2*$C38/SQRT(PI()*D$9*D$10))) -> 0.00031525459 | E38: =E$8*E$10*(1-EXP(-2*$C38/SQRT(PI()*E$9*E$10))) -> 0.00017708628 | F38: =F$8*F$10*(1-EXP(-2*$C38/SQRT(PI()*F$9*F$10))) -> 0.00013258786 | G38: =G$8*G$10*(1-EXP(-2*$C38/SQRT(PI()*G$9*G$10))) -> 8.8543138e-05 | H38: =H$8*H$10*(1-EXP(-2*$C38/SQRT(PI()*H$9*H$10))) -> 3.1525459e-05
C39: 2.7 | D39: =D$8*D$10*(1-EXP(-2*$C39/SQRT(PI()*D$9*D$10))) -> 0.00032248297 | E39: =E$8*E$10*(1-EXP(-2*$C39/SQRT(PI()*E$9*E$10))) -> 0.00018253815 | F39: =F$8*F$10*(1-EXP(-2*$C39/SQRT(PI()*F$9*F$10))) -> 0.00013695121 | G39: =G$8*G$10*(1-EXP(-2*$C39/SQRT(PI()*G$9*G$10))) -> 9.1269076e-05 | H39: =H$8*H$10*(1-EXP(-2*$C39/SQRT(PI()*H$9*H$10))) -> 3.2248297e-05
C40: 2.8 | D40: =D$8*D$10*(1-EXP(-2*$C40/SQRT(PI()*D$9*D$10))) -> 0.00032945796 | E40: =E$8*E$10*(1-EXP(-2*$C40/SQRT(PI()*E$9*E$10))) -> 0.00018790372 | F40: =F$8*F$10*(1-EXP(-2*$C40/SQRT(PI()*F$9*F$10))) -> 0.0001412656 | G40: =G$8*G$10*(1-EXP(-2*$C40/SQRT(PI()*G$9*G$10))) -> 9.395186e-05 | H40: =H$8*H$10*(1-EXP(-2*$C40/SQRT(PI()*H$9*H$10))) -> 3.2945796e-05
C41: 2.9 | D41: =D$8*D$10*(1-EXP(-2*$C41/SQRT(PI()*D$9*D$10))) -> 0.00033618846 | E41: =E$8*E$10*(1-EXP(-2*$C41/SQRT(PI()*E$9*E$10))) -> 0.00019318435 | F41: =F$8*F$10*(1-EXP(-2*$C41/SQRT(PI()*F$9*F$10))) -> 0.00014553158 | G41: =G$8*G$10*(1-EXP(-2*$C41/SQRT(PI()*G$9*G$10))) -> 9.6592173e-05 | H41: =H$8*H$10*(1-EXP(-2*$C41/SQRT(PI()*H$9*H$10))) -> 3.3618846e-05
C42: 3 | D42: =D$8*D$10*(1-EXP(-2*$C42/SQRT(PI()*D$9*D$10))) -> 0.00034268304 | E42: =E$8*E$10*(1-EXP(-2*$C42/SQRT(PI()*E$9*E$10))) -> 0.00019838137 | F42: =F$8*F$10*(1-EXP(-2*$C42/SQRT(PI()*F$9*F$10))) -> 0.00014974969 | G42: =G$8*G$10*(1-EXP(-2*$C42/SQRT(PI()*G$9*G$10))) -> 9.9190687e-05 | H42: =H$8*H$10*(1-EXP(-2*$C42/SQRT(PI()*H$9*H$10))) -> 3.4268304e-05
... C1012: 100 | D1012: =D$8*D$10*(1-EXP(-2*$C1012/SQRT(PI()*D$9*D$10))) -> 0.00052146519 | E1012: =E$8*E$10*(1-EXP(-2*$C1012/SQRT(PI()*E$9*E$10))) -> 0.00052146513 | F1012: =F$8*F$10*(1-EXP(-2*$C1012/SQRT(PI()*F$9*F$10))) -> 0.00052145864 | G1012: =G$8*G$10*(1-EXP(-2*$C1012/SQRT(PI()*G$9*G$10))) -> 0.00026073257 | H1012: =H$8*H$10*(1-EXP(-2*$C1012/SQRT(PI()*H$9*H$10))) -> 5.2146519e-05

Sheet HandCalculations-4He
F1: Rock bulk density = | G1: 2.65 | H1: kg solid / dm3 solid | P1: V871 | Q1: V842
B2: 4He | C2: Concentrations in ppm | F2: ingrowth rate of 4He in [mol dm-3 solid s-1] | I2: total R [mol dm-3 solid s-1] | J2: Time [yrs] | N2: handcalculation | P2: simulated | Q2: simulated
C3: U235 | D3: U238 | E3: Th232 | F3: R_4He_235U | G3: R_4He_238U | H3: R_4He_232Th | I3: R | J3: Time [yrs] | K3: t [s] | L3: R*t [mol dm-3 solid] | M3: Porosity [-] | N3: c_4He [mol/L H2O] | R3: R_4He back calculated from the 3He concentration
C4: 0.02 | D4: 2.78 | E4: 10.7 | F4: =0.001*C15*D15*C4*G1/E15 -> 4.925617e-23 | G4: =0.001*C16*D16*D4*G1/E16 -> 1.2183408e-21 | H4: =0.001*C17*D17*E4*G1/E17 -> 1.1513108e-21 | I4: =F4+G4+H4 -> 2.4189078e-21 | J4: 100000000 | K4: =J4*365*86400 -> 3.1536e+15 | L4: =I4*K4 -> 7.6282676e-06 | M4: 1e-06 | N4: =L4/M4 -> 7.6282676 | P4: 7.629438 | R4: =P4*M4/K4 -> 2.4192789e-21
C13: Yield coefficient | D13: α-decay constant
B14: Radioelement | C14: Y_(_^4)He,i^α [-] | D14: λ_i^α [s-1] | E14: Molar mass of radioelement 〖RE〗_i^s [g mol-1]
B15: 235U | C15: 7 | D15: 3.12e-17 | E15: 235
B16: 238U | C16: 8 | D16: 4.92e-18 | E16: 238
B17: 232Th | C17: 6 | D17: 1.57e-18 | E17: 232

Sheet 3He-HandCalculations
F1: Rock bulk density = | H1: 2.65 | I1: kg solid / dm3 solid | R1: V871
B2: 3He | C2: Concentrations in ppm | F2: neutron generation rate in [mol dm-3 solid s-1] | J2: total R [mol dm-3 solid s-1] | L2: Time [yrs] | P2: handcalculation | R2: simulated
C3: U235 | D3: U238 | E3: Th232 | F3: R_n_sf_238U | G3: R_n_sf_232Th | H3: R_n_a_(238+235)U | I3: R_n_a_232Th | J3: R_n_tot | K3: R_3He | L3: Time [yrs] | M3: t [s] | N3: R_3He*t [mol dm-3 solid] | O3: Porosity [-] | P3: c_4He [mol/L H2O] | X3: R_3He back calculated from the 3He concentration
C4: 0.02 | D4: 2.78 | E4: 10.7 | F4: =0.001*C16*D16*D4*H1/E16 -> 1.8386546e-28 | G4: =0.001*C17*D17*E4*H1/E17 -> 2.0471821e-32 | H4: =(C4+D4)*H1*(Q15*R15+Q16*R16+Q17*R17+Q18*R18+Q19*R19) -> 5.0012581e-28 | I4: =E4*H1*(Q20*R15+Q21*R16+R22*R17+Q23*R18+Q24*R19) -> 8.7784733e-28 | J4: =F4+H4+I4+G4 -> 1.5618591e-27 | K4: =J4*M6*V15 -> 2.6114284e-29 | L4: 100000000 | M4: =L4*365*86400 -> 3.1536e+15 | N4: =K4*M4 -> 8.2354005e-14 | O4: 1e-06 | P4: =N4/O4 -> 8.2354005e-08 | R4: 8.21407e-08 | S4: if 3He only | T4: vaiable radioelement concentration - default- radioelement concentration decrease due to radioactive dacay | X4: =R4*$O$4/$M$4 -> 2.6046645e-29
R5: 8.232984e-08 | S5: if 3He only | T5: constant radioelement concentration' | X5: =R5*$O$4/$M$4 -> 2.6106621e-29
L6: P_th= | M6: 0.8 | S6: if all NGs | T6: constant radioelement concentration'
Q9: =(P4-R5)/P4*100 -> 0.029342803
Q10: =(K4-X5)/X5*100 -> 0.029351415
B14: Radioelement | C14: Y_(n,i^sf [-] | D14: λ_i^sf [s-1] | E14: Molar mass of radioelement 〖RE〗_i^s [g mol-1] | N14: Radioelement | O14: Element | P14: Empirical yield factors Y_(n,ij)^α [mol kg solid kg-1 E mg-1 RE s-1] | Q14: Y_(n,ij)^a | R14: weight fraction [kg E/(kg solid)] | V14: F_6Li [-]
B15: 235U | N15: 238U + 235U | O15: Na | P15: 7.3 x 10-28 | Q15: 7.3e-28 | R15: 0.0289 | S15: 'na' | V15: 0.0209
B16: 238U | C16: 2.2 | D16: 2.7e-24 | E16: 238 | O16: Mg | P16: 2.8 x 10-28 | Q16: 2.8e-28 | R16: 0.0133 | S16: 'mg'
B17: 232Th | C17: 2.5 | D17: 6.7e-29 | E17: 232 | O17: Al | P17: 2.6 x 10-28 | Q17: 2.6e-28 | R17: 0.0804 | S17: 'al' | V17: The determined thermal neutron radiative capture cross section of 6Li was 37.7 ± 3.0 mb.
O18: Si | P18: 6.9 x 10-29 | Q18: 6.9e-29 | R18: 0.309 | S18: 'si' | V18: 6Li abundance | X18: 0.076
O19: C | P19: 1.1 x 10-28 | Q19: 1.1e-28 | R19: 0.00324 | S19: 'c' | V19: This result is in perfect agreement with the experimental value of 45.4 ± 3 mbarn (Lynn et al. 1991).
N20: 232Th | O20: Na | P20: 3.2 x 10-28 | Q20: 3.2e-28
O21: Mg | P21: 1.3 x 10-28 | Q21: 1.3e-28 | V21: rel. abundance | W21: thermal neutron capture cross section [mbarns]
O22: Al | P22: 1.3 x 10-28 | Q22: 1.3e-28 | R22: =Q21*2.55/2.45 -> 1.3530612e-28 | U22: 6Li | V22: 0.076 | W22: 37.7
O23: Si | P23: 2.9 x 10-29 | Q23: 2.9e-29 | U23: 7Li | V23: =1-V22 -> 0.924 | W23: 45.4
O24: C | P24: 4.4 x 10-29 | Q24: 4.4e-29 | U24: F_Li = | V24: =0.000205/0.00979 -> 0.020939734 | W24: - | X24: for average upper crust
U25: F_6Li= | V25: =V24*V22*W22/(V22*W22+V23*W23) -> 0.0013387659
U26: F_7Li = | V26: =V24*V23*W23/(V22*W22+V23*W23) -> 0.019600969

Sheet Ne-handCalc
C1: RE_j^s | F1: Rock bulk density = | H1: 2.65 | I1: kg solid / dm3 solid | M1: V871
B2: 20Ne | C2: Concentrations in ppm | F2: the rate of 20Ne ingrowth [mol dm-3 solid s-1] | K2: handcalculation | M2: simulated
C3: U235 | D3: U238 | E3: Th232 | F3: R_nu_O_Na | G3: Time [yrs] | H3: t [s] | I3: R_20Ne*t [mol dm-3 solid] | J3: Porosity [-] | K3: c_20Ne [mol/L H2O] | O3: R_4He back calculated from the 3He concentration
C4: 0.02 | D4: 2.78 | E4: 10.7 | F4: =E20*H1*(H20*G34*(L20*(C4+D4)+M20*E4) + I21*G29*((C4+D4)*L21+E4*M21)) -> 1.0906388e-29 | G4: 100000000 | H4: =G4*365*86400 -> 3.1536e+15 | I4: =F4*H4 -> 3.4394386e-14 | J4: 1e-06 | K4: =I4/J4 -> 3.4394386e-08 | M4: 3.442824e-08 | O4: =M4*J4/H4 -> 1.0917123e-29
C6: RE_j^s | F6: Rock bulk density = | H6: 2.65 | I6: kg solid / dm3 solid | M6: V871
B7: 21Ne | C7: Concentrations in ppm | F7: the rate of 21Ne ingrowth [mol dm-3 solid s-1] | K7: handcalculation | M7: simulated
C8: U235 | D8: U238 | E8: Th232 | F8: R_nu_O_Mg | G8: Time [yrs] | H8: t [s] | I8: R_21Ne*t [mol dm-3 solid] | J8: Porosity [-] | K8: c_20Ne [mol/L H2O]
C9: 0.02 | D9: 2.78 | E9: 10.7 | F9: =E22*H6*(H22*G34*(L22*(C9+D9)+M22*E9) + J23*G30*((C9+D9)*L23+E9*N23)) -> 1.0911337e-28 | G9: 100000000 | H9: =G9*365*86400 -> 3.1536e+15 | I9: =F9*H9 -> 3.4409992e-13 | J9: 1e-06 | K9: =I9/J9 -> 3.4409992e-07 | M9: 3.441423e-07 | O9: =M9*J9/H9 -> 1.0912681e-28
C11: RE_j^s | F11: Rock bulk density = | H11: 2.65 | I11: kg solid / dm3 solid | M11: V871
B12: 22Ne | C12: Concentrations in ppm | F12: the rate of 22Ne ingrowth [mol dm-3 solid s-1] | K12: handcalculation | M12: simulated
C13: U235 | D13: U238 | E13: Th232 | F13: R_nu_F_Mg | G13: Time [yrs] | H13: t [s] | I13: R_22Ne*t [mol dm-3 solid] | J13: Porosity [-] | K13: c_20Ne [mol/L H2O]
C14: 0.02 | D14: 2.78 | E14: 10.7 | F14: =E24*H11*(K24*G36*(L24*(C14+D14)+M24*E14) + J25*G30*((C14+D14)*L25+E14*M25)) -> 1.4238252e-31 | G14: 100000000 | H14: =G14*365*86400 -> 3.1536e+15 | I14: =F14*H14 -> 4.4901751e-16 | J14: 1e-06 | K14: =I14/J14 -> 4.4901751e-10 | M14: 4.49086e-10 | O14: =M14*J14/H14 -> 1.4240424e-31
H17: for | L17: for
D19: Ne isotope | H19: O | I19: Na | J19: Mg | K19: F | L19: U | M19: Th
C20: 20 | D20: 20Ne | E20: 1.41e-29 | F20: 2 | G20: 2 | H20: 1 | L20: 0.144 | M20: 0.0174
G21: 2 | I21: 1 | L21: 0.141 | M21: 0.00169
C22: 21 | D22: 21Ne | E22: 1.41e-29 | F22: 2 | G22: 2 | H22: 1 | L22: 1.48 | M22: 0.186
G23: 2 | J23: 1 | L23: 0.105 | M23: 0.0173 | N23: 0.0179
C24: 22 | D24: 22Ne | E24: 1.41e-31 | F24: 2 | G24: 2 | K24: =10^4 -> 10000 | L24: 3.06 | M24: 0.417
G25: 2 | J25: 1 | L25: 4.2 | M25: 0.663
G28: E_i^s [weight fraction]
G29: 0.0289 | H29: 'na'
G30: 0.0133 | H30: 'mg'
G31: 0.0804 | H31: 'al'
G32: 0.309 | H32: 'si'
G33: 0.00324 | H33: 'c'
G34: 0.475 | H34: 'o'
G35: 0.000232 | H35: 'cl'
G36: 1e-06 | H36: 'f'

Sheet Ar-HandCalc
F1: Rock bulk density = | H1: 2.65 | I1: kg solid / dm3 solid | R1: V871 | U1: d:\Projects\Project_23-25\NGs-ingrowth\40Ar36Ar38Ar\
C2: Concentrations in ppm | F2: neutron generation rate in [mol dm-3 solid s-1] | J2: total R [mol dm-3 solid s-1] | L2: Time [yrs] | P2: handcalculation | R2: simulated
C3: U235 | D3: U238 | E3: Th232 | F3: R_n_sf_238U | G3: R_n_sf_232Th | H3: R_n_a_(238+235)U | I3: R_n_a_232Th | J3: R_n_tot | K3: R_Ar | L3: Time [yrs] | M3: t [s] | N3: R_Ar*t [mol dm-3 solid] | O3: Porosity [-] | P3: c_Ar [mol/L H2O] | T3: R_Ar back calculated from the 3He concentration
B4: 36Ar | C4: 0.02 | D4: 2.78 | E4: 10.7 | F4: =0.001*C16*D16*D4*H1/E16 -> 1.8386546e-28 | G4: =0.001*C17*D17*E4*H1/E17 -> 2.0471821e-32 | H4: =(C4+D4)*H1*(Q15*R15+Q16*R16+Q17*R17+Q18*R18+Q19*R19) -> 5.0012581e-28 | I4: =E4*H1*(Q20*R15+Q21*R16+Q22*R17+Q23*R18+Q24*R19) -> 8.7714945e-28 | J4: =F4+H4+I4+G4 -> 1.5611612e-27 | K4: =J4*M5*U15*K5 -> 2.6577538e-29 | L4: 100000000 | M4: =L4*365*86400 -> 3.1536e+15 | N4: =K4*M4 -> 8.3814923e-14 | O4: 1e-06 | P4: =N4/O4 -> 8.3814923e-08 | R4: 8.382675e-08 | S4: if all NGs | T4: =R4*O4/M4 -> 2.6581288e-29
J5: P_th= | K5: 0.8 | L5: 𝑌_(_^36)𝐴𝑟^𝛽= | M5: 0.95 | R5: 8.382675e-08 | S5: if 36Ar only
C6: =C2 -> Concentrations in ppm | F6: =F2 -> neutron generation rate in [mol dm-3 solid s-1] | J6: =J2 -> total R [mol dm-3 solid s-1] | R6: =R1 -> V871
C7: =C3 -> U235 | D7: =D3 -> U238 | E7: =E3 -> Th232 | F7: =F3 -> R_n_sf_238U | G7: =G3 -> R_n_sf_232Th | H7: =H3 -> R_n_a_(238+235)U | I7: =I3 -> R_n_a_232Th | J7: =J3 -> R_n_tot | ... P7: =P3 -> c_Ar [mol/L H2O] | R7: =R2 -> simulated
B8: 38Ar_tmc | C8: =C4 -> 0.02 | D8: =D4 -> 2.78 | E8: =E4 -> 10.7 | F8: =F4 -> 1.8386546e-28 | G8: =G4 -> 2.0471821e-32 | H8: =H4 -> 5.0012581e-28 | I8: =I4 -> 8.7714945e-28 | J8: =J4 -> 1.5611612e-27 | K8: =J8*M9*V15+F10 -> 3.7039837e-31 | L8: =L4 -> 100000000 | M8: =M4 -> 3.1536e+15 | N8: =K8*M8 -> 1.1680883e-15 | O8: =O4 -> 1e-06 | P8: =N8/O8 -> 1.1680883e-09 | R8: 1.16814e-09 | S8: if all NGs | T8: =R8*O8/M8 -> 3.7041476e-31
F9: R_nu_38Ar | K9: || | L9: P_th= | M9: 0.8 | R9: 1.16814e-09 | S9: if 38Ar only
B10: 38Ar_nu | C10: =C8 -> 0.02 | D10: =D8 -> 2.78 | E10: =E8 -> 10.7 | F10: =B23*H1*(E22*I20*(F22*(C10+D10)+G22*E10)) -> 2.8093458e-31 | K10: R_tmc+Rnu
J12: R_tmc= | K12: =J8*M9*V15 -> 8.9463784e-32
B14: Radioelement | C14: Y_(n,i^sf [-] | D14: λ_i^sf [s-1] | E14: Molar mass of radioelement 〖RE〗_i^s [g mol-1] | N14: Radioelement | O14: Element | P14: Empirical yield factors Y_(n,ij)^α [mol kg solid kg-1 E mg-1 RE s-1] | Q14: Y_(n,ij)^a | R14: weight fraction [kg E/(kg solid)] | U14: F_35Cl [-] | V14: F_37Cl [-]
B15: 235U | N15: 238U + 235U | O15: Na | P15: 7.3 x 10-28 | Q15: 7.3e-28 | R15: 0.0289 | S15: 'na' | U15: ='Ar-handCalculation-BB'!H13 -> 0.022400278 | V15: ='Ar-handCalculation-BB'!H14 -> 7.1632404e-05 | W15: used values
B16: 238U | C16: 2.2 | D16: 2.7e-24 | E16: 238 | O16: Mg | P16: 2.8 x 10-28 | Q16: 2.8e-28 | R16: 0.0133 | S16: 'mg'
B17: 232Th | C17: 2.5 | D17: 6.7e-29 | E17: 232 | O17: Al | P17: 2.6 x 10-28 | Q17: 2.6e-28 | R17: 0.0804 | S17: 'al'
B18: For 38Ar_nu | O18: Si | P18: 6.9 x 10-29 | Q18: 6.9e-29 | R18: 0.309 | S18: 'si'
E19: for | F19: for | I19: weight fraction [kg E/(kg solid)] | O19: C | P19: 1.1 x 10-28 | Q19: 1.1e-28 | R19: 0.00324 | S19: 'c'
I20: 0.000232 | J20: cl' | N20: 232Th | O20: Na | P20: 3.2 x 10-28 | Q20: 3.2e-28
E21: Cl | F21: U | G21: Th | O21: Mg | P21: 1.3 x 10-28 | Q21: 1.3e-28
B22: 1.41 x 10-28 | C22: 1 | D22: 2 | E22: 1 | F22: 0.76 | G22: 0.104 | O22: Al | P22: 1.3 x 10-28 | Q22: =1.35E-28 -> 1.35e-28
B23: 1.41e-28 | O23: Si | P23: 2.9 x 10-29 | Q23: 2.9e-29
O24: C | P24: 4.4 x 10-29 | Q24: 4.4e-29
B26: 40Ar
E28: Rock bulk density = | F28: 2.65 | G28: kg solid / dm3 solid | O28: V871
B29: Concentrations in ppm | E29: ingrowth rate of 40Ar in [mol dm-3 solid s-1] | H29: total R [mol dm-3 solid s-1] | I29: Time [yrs] | M29: handcalculation | O29: simulated
B30: 40K | E30: R_40Ar_40K | H30: R | I30: Time [yrs] | J30: t [s] | K30: R*t [mol dm-3 solid] | L30: Porosity [-] | M30: c_40Ar [mol/L H2O]
B31: 3 | E31: =0.001*C37*D37*B31*F28/E38 -> 3.6139077e-22 | H31: =E31+F31+G31 -> 3.6139077e-22 | I31: 100000000 | J31: =I31*365*86400 -> 3.1536e+15 | K31: =H31*J31 -> 1.1396819e-06 | L31: 1e-06 | M31: =K31/L31 -> 1.1396819 | O31: 1.138717 | P31: if all NGs | Q31: =O31*L31/J31 -> 3.6108479e-22
O32: 1.138717 | P32: if 40Ar only
B35: Radioelement | C35: Yield coefficient | D35: Decay constant | E35: Molar mass of radioelement
C36: [-] | D36: [s-1] | E36: [g mol-1]
B37: 40K | C37: 0.105 | D37: 1.73e-17 | E37: 40
E38: 39.96

Sheet KrXe-HandCalc
E1: Rock bulk density = | F1: 2.65 | G1: kg solid / dm3 solid | J1: p_th= | K1: 0.8 | O1: V871
C2: Concentrations in ppm | E2: ingrowth rate of 4He in [mol dm-3 solid s-1] | H2: total R [mol dm-3 solid s-1] | I2: Time [yrs] | M2: handcalculation | O2: simulated
D3: U238 | F3: R_sf_238U | G3: R_tnc_235U | H3: R | I3: Time [yrs] | J3: t [s] | K3: R*t [mol dm-3 solid] | L3: Porosity [-] | M3: c_4He [mol/L H2O] | O3: all NGs | P3: Kr or Xe only | Q3: R_Ar back calculated from the 3He concentration
C4: 83Kr | D4: 2.78 | F4: =0.001*N18*$C$16*D4*$F$1/$C$20 -> 3.1591429e-32 | G4: =$K$1*O18*'Ar-HandCalc'!$J$4*$A$26 -> 3.5356936e-35 | H4: =F4+G4 -> 3.1626786e-32 | I4: 100000000 | J4: =I4*365*86400 -> 3.1536e+15 | K4: =H4*J4 -> 9.9738233e-17 | L4: 1e-06 | M4: =K4/L4 -> 9.9738233e-11 | O4: 9.975354e-11 | P4: 9.975354e-11 | Q4: =O4*L4/J4 -> 3.163164e-32
C5: 84Kr | D5: 2.78 | F5: =0.001*N19*$C$16*D5*$F$1/$C$20 -> 1.0446901e-31 | G5: =$K$1*O19*'Ar-HandCalc'!$J$4*$A$26 -> 6.5452042e-35 | H5: =F5+G5 -> 1.0453446e-31 | I5: 100000001 | J5: =I5*365*86400 -> 3.1536e+15 | K5: =H5*J5 -> 3.2965989e-16 | L5: 1e-06 | M5: =K5/L5 -> 3.2965989e-10 | O5: 3.297105e-10 | P5: 3.297105e-10 | Q5: =O5*L5/J5 -> 1.0455051e-31
C6: 86Kr | D6: 2.78 | F6: =0.001*N20*$C$16*D6*$F$1/$C$20 -> 6.5857266e-31 | G6: =$K$1*O20*'Ar-HandCalc'!$J$4*$A$26 -> 1.3090408e-34 | H6: =F6+G6 -> 6.5870356e-31 | I6: 100000002 | J6: =I6*365*86400 -> 3.1536001e+15 | K6: =H6*J6 -> 2.0772876e-15 | L6: 1e-06 | M6: =K6/L6 -> 2.0772876e-09 | O6: 2.077606e-09 | P6: 2.077606e-09 | Q6: =O6*L6/J6 -> 6.5880453e-31
C7: 129Xe | D7: 2.78 | F7: =0.001*N21*$C$16*D7*$F$1/$C$20 -> 1.0530476e-32 | G7: =$K$1*O21*'Ar-HandCalc'!$J$4*$A$26 -> 6.2307777e-35 | H7: =F7+G7 -> 1.0592784e-32 | I7: 100000003 | J7: =I7*365*86400 -> 3.1536001e+15 | K7: =H7*J7 -> 3.3405405e-17 | L7: 1e-06 | M7: =K7/L7 -> 3.3405405e-11 | O7: 3.341053e-11 | P7: 3.341053e-11 | Q7: =O7*L7/J7 -> 1.0594409e-32
C8: 131Xe | D8: 2.78 | F8: =0.001*N22*$C$16*D8*$F$1/$C$20 -> 4.0032526e-31 | G8: =$K$1*O22*'Ar-HandCalc'!$J$4*$A$26 -> 1.880142e-34 | H8: =F8+G8 -> 4.0051327e-31 | I8: 100000004 | J8: =I8*365*86400 -> 3.1536001e+15 | K8: =H8*J8 -> 1.2630587e-15 | L8: 1e-06 | M8: =K8/L8 -> 1.2630587e-09 | O8: 1.263253e-09 | P8: 1.263253e-09 | Q8: =O8*L8/J8 -> 4.0057488e-31
C9: 132Xe | D9: 2.78 | F9: =0.001*N23*$C$16*D9*$F$1/$C$20 -> 3.1340704e-30 | G9: =$K$1*O23*'Ar-HandCalc'!$J$4*$A$26 -> 2.8105877e-34 | H9: =F9+G9 -> 3.1343514e-30 | I9: 100000005 | J9: =I9*365*86400 -> 3.1536002e+15 | K9: =H9*J9 -> 9.8844912e-15 | L9: 1e-06 | M9: =K9/L9 -> 9.8844912e-09 | O9: 9.886008e-09 | P9: 9.886008e-09 | Q9: =O9*L9/J9 -> 3.1348324e-30
C10: 134Xe | D10: 2.78 | F10: =0.001*N24*$C$16*D10*$F$1/$C$20 -> 4.379341e-30 | G10: =$K$1*O24*'Ar-HandCalc'!$J$4*$A$26 -> 5.1912453e-34 | H10: =F10+G10 -> 4.3798601e-30 | I10: 100000006 | J10: =I10*365*86400 -> 3.1536002e+15 | K10: =H10*J10 -> 1.3812328e-14 | L10: 1e-06 | M10: =K10/L10 -> 1.3812328e-08 | O10: 1.381445e-08 | P10: 1.381445e-08 | Q10: =O10*L10/J10 -> 4.3805331e-30
C11: 136Xe | D11: 2.78 | F11: =0.001*N25*$C$16*D11*$F$1/$C$20 -> 5.2652382e-30 | G11: =$K$1*O25*'Ar-HandCalc'!$J$4*$A$26 -> 4.1517128e-34 | H11: =F11+G11 -> 5.2656534e-30 | I11: 100000007 | J11: =I11*365*86400 -> 3.1536002e+15 | K11: =H11*J11 -> 1.6605766e-14 | L11: 1e-06 | M11: =K11/L11 -> 1.6605766e-08 | O11: 1.660831e-08 | P11: 1.660831e-08 | Q11: =O11*L11/J11 -> 5.2664602e-30
A14: radioelements' ; in the database | P14: Noble gas isotope | Q14: Spontaneous fission of 238U: Yield factor [-] | R14: Neutron capture by 235U: Yield factor [-]
Q15: and | R15: and
A16: '238u' | C16: 2.7e-24 | F16: =0.00000000000000009/(365*86400) -> 2.8538813e-24
A17: spontaneous fission' 2.7e-24 ;lamda_sf, table 1? | F17: [s-1] | I17: =0.001* 0.063 *(2.7E-24) * 2.78 * 2.65/238 -> 5.2652382e-30
A18: 'first order decay' 4.92e-18 ;lamda_alpha, table 3, use keyword 'alpha decay'? | M18: 83Kr | N18: 0.000378 | O18: 0.00551 | P18: 83Kr | Q18: 0.0004 | R18: 0.0055
A19: 'molar mass' 238.0 ;gfw_re, gram formula weight of radioelement, table 1 | M19: 84Kr | N19: 0.00125 | O19: 0.0102 | P19: 84Kr | Q19: 0.0013 | R19: 0.0102
C20: 238 | D20: [g/mol] | M20: 86Kr | N20: 0.00788 | O20: 0.0204 | P20: 86Kr | Q20: 0.0079 | R20: 0.0204
A21: !Fron input file *.dat, block 15: IC-RT | M21: 129Xe | N21: 0.000126 | O21: 0.00971 | P21: 129Xe | Q21: 0.000126 | R21: 0.0097
A22: 'noble gas ingrowth - neutron capture probability' !unitless | M22: 131Xe | N22: 0.00479 | O22: 0.0293 | P22: 131Xe | Q22: 0.0048 | R22: 0.0293
A23: 0.000205 | B23: '6li' !F_(_^6)Li is the fraction of neutrons captured by 6Li [-] | M23: 132Xe | N23: 0.0375 | O23: 0.0438 | P23: 132Xe | Q23: 0.0375 | R23: 0.0438
A24: 0.000167 | B24: '35cl' !76% 35Cl, 24% 37Cl | M24: 134Xe | N24: 0.0524 | O24: 0.0809 | P24: 134Xe | Q24: 0.05242 | R24: 0.0809
A25: 5.3e-05 | B25: '37cl' | M25: 136Xe | N25: 0.063 | O25: 0.0647 | P25: 136Xe | Q25: 0.063 | R25: 0.0647
A26: =0.0000000503/0.00979 -> 5.1378958e-06 | B26: '235u' | C26: ='KrXe-handCalculation-BB'!J9 -> 5.1378958e-06

Sheet neutronProduction-BB
C1: Verification calculation directly based on B&B (2002) in order to verify the unit coversion. | L1: Method: calculate the neutron production according to eqn (1) in B&B (2002)
D2: 3 main types of reaction producing neutrons in the crust:
D3: 1) Cosmic ray interaction | G3: ->> only important within the top few meters of the crust, neglected
D4: 2) alpha particle interaction with light nuclei | P4: Element | Q4: Weight fraction [-] | R4: weight percent [%]
D5: 3) spontaneous fission | P5: Na | Q5: ='3He-HandCalculations'!R15 -> 0.0289 | R5: =Q5*100 -> 2.89
P6: Mg | Q6: ='3He-HandCalculations'!R16 -> 0.0133 | R6: =Q6*100 -> 1.33
D7: neutron production rate by (alpha,n)reactions | P7: Al | Q7: ='3He-HandCalculations'!R17 -> 0.0804 | R7: =Q7*100 -> 8.04
D8: 1) (alpha,n)238U | P8: Si | Q8: ='3He-HandCalculations'!R18 -> 0.309 | R8: =Q8*100 -> 30.9
D9: 2) (alpha,n)235U | P9: C | Q9: ='3He-HandCalculations'!R19 -> 0.00324 | R9: =Q9*100 -> 0.324
D10: 3) (alpha,n)232Th
D12: (α,n)U = | E12: =0.01*S24*(13.8*R5+5.4*R6+5*R7+1.31*R8+2*R9) -> 3.594948 | F12: =H37 -> # of nutrons/(g solid year)
D13: =D32 -> = | E13: =E12/$L$30 -> 5.9687e-24 | F13: =H33 -> mol of nutrons/(g solid year)
D14: =D33 -> = | E14: =E13*$P$34*1000 -> 1.5817055e-20 | F14: =H34 -> mol of nutrons/(dm3 year)
D15: =D34 -> = | E15: =E14/(365*86400) -> 5.0155552e-28 | F15: =H35 -> mol of nutrons/(dm3 s)
D17: (α,n)Th = | E17: =0.01*O27*(6*R5+2.45*R6+2.55*R7+0.56*R8+0.83*R9) -> 6.2780559 | F17: =F12 -> # of nutrons/(g solid year)
D18: =D13 -> = | E18: =E17/$L$30 -> 1.042347e-23 | F18: =F13 -> mol of nutrons/(g solid year)
D19: =D14 -> = | E19: =E18*$P$34*1000 -> 2.7622195e-20 | F19: =F14 -> mol of nutrons/(dm3 year)
D20: =D15 -> = | E20: =E19/(365*86400) -> 8.7589407e-28 | F20: =F15 -> mol of nutrons/(dm3 s)
C22: Spontaneous fission: main contribution is from 238U, those from SFs of 235U can be neglected
C24: 238U | D24: Yield factor: | F24: 2.2 | G24: n per fission | K24: (Eikenberg et al. 1993) | N24: [238U]= | O24: ='3He-HandCalculations'!D4 -> 2.78 | P24: ppm | Q24: [U]=[235U]+[238U]= | S24: =O24+O25 -> 2.8 | T24: ppm
D25: Decay constant (λf): | F25: 8.6e-17 | G25: years^-1 = | H25: =F25/(365*86400) -> 2.7270421e-24 | I25: s^-1 | K25: (Eikenberg et al. 1993) | N25: [235U]= | O25: ='3He-HandCalculations'!C4 -> 0.02 | P25: ppm
C27: 232Th | D27: Yield factor: | F27: 2.5 | G27: n per fission | K27: (Wieler and Eikenberg 1999) | N27: [232Th]= | O27: ='3He-HandCalculations'!E4 -> 10.7 | P27: ppm
D28: Decay constant: | F28: 2.1e-21 | G28: years^-1 = | H28: =F28/(365*86400) -> 6.6590563e-29 | I28: s^-1 | K28: (Wieler and Eikenberg 1999)
D30: (sf,n)U=(N_A/A_U)*λf*yield*[U]*1e-6 | H30: # of nutrons/(g solid year) | K30: N_A= | L30: 6.023e+23
D31: (sf,n)U = | E31: (L20/L21)*F15*yield*[U]*1e-6 | K31: A_U= | L31: 238 | M31: g/mol
D32: = | E32: =($L$30/$L$31)*F25*F24*O24*0.000001 -> 1.3310729 | H32: =H30 -> # of nutrons/(g solid year)
D33: = | E33: =E32/$L$30 -> 2.2099832e-24 | H33: mol of nutrons/(g solid year) | N33: 1 ppm = | O33: 1 | P33: mg/kg solid = | Q33: 0.001 | R33: g/kg solid
D34: = | E34: =E33*$Q$33*$P$34/0.000001 -> 5.8564555e-21 | H34: mol of nutrons/(dm3 year) | N34: Rock density ρ_s = | P34: ='3He-HandCalculations'!H1 -> 2.65 | Q34: ='3He-HandCalculations'!I1 -> kg solid / dm3 solid | R34: =P34*1000 -> 2650 | S34: g solid/dm3 solid
D35: = | E35: =E34/(365*86400) -> 1.8570698e-28 | H35: mol of nutrons/(dm3 s)
D37: (sf,n)Th=(N_A/A_Th)*λf*yield*[Th]*1e-6 | H37: # of nutrons/(g solid year)
D38: (sf,n)Th = | E38: (L20/L21)*F15*yield*[Th]*1e-6
D39: = | E39: =($L$30/$L$31)*F28*F27*O27*0.000001 -> 0.00014216051 | H39: =H37 -> # of nutrons/(g solid year)
D40: = | E40: =E39/$L$30 -> 2.3602941e-28 | H40: mol of nutrons/(g solid year)
D41: = | E41: =E40*$Q$33*$P$34/0.000001 -> 6.2547794e-25 | H41: mol of nutrons/(dm3 year)
D42: = | E42: =E41/(365*86400) -> 1.9833775e-32 | H42: mol of nutrons/(dm3 s)
D45: Total nutron generation rate R_n in mol/(dm3 s)
D46: R_n = (α,n)U +(α,n)Th +(sf,n)U + (sf,n)Th =
D47: =D40 -> = | E47: =E15+E20+E35+E42 -> 1.5631764e-27 | H47: =H42 -> mol of nutrons/(dm3 s)
D50: Hand calculated based on TM Noble gases (Mayer et al. 2023) | J50: 3He-HandCalculations
D51: R_n= | E51: ='3He-HandCalculations'!J4 -> 1.5618591e-27 | H51: ='3He-HandCalculations'!J2 -> total R [mol dm-3 solid s-1]
...

Sheet He-handCalculation-BB
B1: Verification calculation directly based on B&B (2002) in order to verify the unit coversion.
B3: 3He production rate: | K3: RE_j^s
B4: r_3He = | C4: P_th*R_n*F6Li | G4: P_th= | H4: 0.8 | I4: - | K4: Concentrations in ppm
B5: = | C5: =H4*H5*H6 -> 0.1876907 | D5: atoms/(g yr) | G5: R_n= | H5: ='neutronProduction-BB'!E12+'neutronProduction-BB'!E17+'neutronProduction-BB'!E32+'neutronProduction-BB'!E39 -> 11.204219 | I5: # of nutrons/(g solid year) | K5: U235 | L5: U238 | M5: Th232 | O5: 1 ppm = | P5: 1 | Q5: mg/kg solid = | R5: 0.001 | S5: g/kg solid
B6: = | C6: =C5/'neutronProduction-BB'!L30 -> 3.1162327e-25 | D6: mol/(g yr) | G6: F6Li= | H6: =0.000205/0.00979 -> 0.020939734 | I6: - | J6: (from table 1 in B&B, and eqn 14 in B&B (2002) | K6: ='Ne-handCalc'!C4 -> 0.02 | L6: ='Ne-handCalc'!D4 -> 2.78 | M6: ='Ne-handCalc'!E4 -> 10.7 | O6: Rock density ρ_s = | Q6: 2.65 | R6: kg solid / dm3 solid
B7: = | C7: =C6*$Q$6*1000 -> 8.2580167e-22 | D7: ='Ne-handCalculation-BB'!D30 -> mol/(dm^3 solid year) | K7: U = U235+U238
B8: = | C8: =C7/(365*86400) -> 2.6185999e-29 | D8: ='Ne-handCalculation-BB'!D31 -> mol/(dm^3 s) | K8: =K6+L6 -> 2.8
B10: MIN3P hand calculation
B11: r_3He= | C11: ='3He-HandCalculations'!K4 -> 2.6114284e-29
B12: error [%] = | C12: =(C11-C8)/C11*100 -> -0.2746214 | D12: %
B15: 4He production rate:
B16: r_4He = | C16: (3.115e6+1.272E5)*[U] + 7.710E5 [Th]
B17: = | C17: =(3115000+127200)*K8 + 771000*M6 -> 17327860 | D17: =D5 -> atoms/(g yr)
B18: = | C18: =C17/'neutronProduction-BB'!L30 -> 2.8769484e-17 | D18: =D6 -> mol/(g yr)
B19: = | C19: =C18*$R$5*$Q$6/0.000001 -> 7.6239132e-14 | D19: =D7 -> mol/(dm^3 solid year)
B20: = | C20: =C19/(365*86400) -> 2.417527e-21 | D20: =D8 -> mol/(dm^3 s)
B22: MIN3P hand calculation
B23: r_4He= | C23: ='HandCalculations-4He'!I4 -> 2.4189078e-21
B24: error [%] = | C24: =(C23-C20)/C23*100 -> 0.057082804 | D24: %

Sheet Ne-handCalculation-BB
B1: Verification calculation directly based on B&B (2002) in order to verify the unit coversion.
B3: 20Ne production rate: | K3: RE_j^s
B4: r_20Ne= | C4: (6.39*[U]+0.770*[Th])*(0.0226*[O]+0.0022*[Na])*1e-22 | H4: cm^3 STP/(g solid year) | K4: Concentrations in ppm
B5: = | C5: =(6.39*K8+0.77*M6)*(0.0226*M17+0.0022*M12)*1E-22 -> 2.8217769e-21 | D5: =H4 -> cm^3 STP/(g solid year) | K5: U235 | L5: U238 | M5: Th232
B6: =B5 -> = | C6: =C5*$M$25 -> 2.5401636e-24 | D6: g/(g solid year) | K6: ='Ne-handCalc'!C4 -> 0.02 | L6: ='Ne-handCalc'!D4 -> 2.78 | M6: ='Ne-handCalc'!E4 -> 10.7
B7: =B6 -> = | C7: =C6/K46 -> 1.2705621e-25 | D7: mol/(g solid year) | K7: U = U235+U238
B8: =B7 -> = | C8: =C7*$M$51*1000 -> 3.3669895e-22 | D8: mol/(dm^3 solid year) | K8: =K6+L6 -> 2.8
B9: =B8 -> = | C9: =C8/(365*86400) -> 1.0676654e-29 | D9: mol/(dm^3 s)
B10: MIN3P hand calculation
B11: r_20Ne= | C11: ='Ne-handCalc'!F4 -> 1.0906388e-29 | D11: =D9 -> mol/(dm^3 s) | K11: ='Ne-handCalc'!G28 -> E_i^s [weight fraction] | M11: E_i^s [w%] | N11: E_i^s [ppm]
B12: error [%] = | C12: =(C11-C9)/C11*100 -> 2.1064241 | D12: % | K12: ='Ne-handCalc'!G29 -> 0.0289 | L12: ='Ne-handCalc'!H29 -> 'na' | M12: =K12*100 -> 2.89
K13: ='Ne-handCalc'!G30 -> 0.0133 | L13: ='Ne-handCalc'!H30 -> 'mg' | M13: =K13*100 -> 1.33
B14: 21Ne production rate: | K14: ='Ne-handCalc'!G31 -> 0.0804 | L14: ='Ne-handCalc'!H31 -> 'al' | M14: =K14*100 -> 8.04
B15: r_21Ne= | C15: ((1.48*[U]+0.186*[Th])*[O] +(0.105*[U]+0.179*[Th])*[Mg])*1e-22 | K15: ='Ne-handCalc'!G32 -> 0.309 | L15: ='Ne-handCalc'!H32 -> 'si' | M15: =K15*100 -> 30.9
B16: = | C16: =((1.48*K8+0.186*M6)*M17 +(0.105*K8+0.179*M6)*M13)*1E-22 -> 2.9431287e-20 | D16: =D5 -> cm^3 STP/(g solid year) | K16: ='Ne-handCalc'!G33 -> 0.00324 | L16: ='Ne-handCalc'!H33 -> 'c' | M16: =K16*100 -> 0.324
B17: =B16 -> = | C17: =C16*$M$25 -> 2.6494044e-23 | D17: =D6 -> g/(g solid year) | K17: ='Ne-handCalc'!G34 -> 0.475 | L17: ='Ne-handCalc'!H34 -> 'o' | M17: =K17*100 -> 47.5
B18: =B17 -> = | C18: =C17/K45 -> 1.2619909e-24 | D18: =D7 -> mol/(g solid year) | K18: ='Ne-handCalc'!G35 -> 0.000232 | L18: ='Ne-handCalc'!H35 -> 'cl' | M18: =K18*100 -> 0.0232
B19: =B18 -> = | C19: =C18*$M$51*1000 -> 3.344276e-21 | D19: =D8 -> mol/(dm^3 solid year) | K19: ='Ne-handCalc'!G36 -> 1e-06 | L19: ='Ne-handCalc'!H36 -> 'f' | M19: =K19*100 -> 0.0001 | N19: =M19*10000 -> 1
B20: =B19 -> = | C20: =C19/(365*86400) -> 1.060463e-28 | D20: =D9 -> mol/(dm^3 s)
B21: MIN3P hand calculation
B22: r_21Ne= | C22: ='Ne-handCalc'!F9 -> 1.0911337e-28
B23: error [%] = | C23: =(C22-C20)/C22*100 -> 2.8109036 | D23: %
K24: Density of neon at STP
B25: 22Ne production rate: | K25: 0.9002 | L25: g/L | M25: =K25/1000 -> 0.0009002 | N25: g/cm^3
B26: r_22Ne= | C26: ((3.06*[U]+0.417*[Th])*([F]*1e4) +(4.20*[U]+0.663*[Th])*[Mg])*1e-24 | K26: molar mass [g/mol]
B27: = | C27: =((3.06*K8+0.417*M6)*M19*10000 +(4.2*K8+0.663*M6)*M13)*1E-24 -> 3.8105853e-23 | D27: =D16 -> cm^3 STP/(g solid year) | K27: molar mass [u]
B28: =B27 -> = | C28: =C27*$M$25 -> 3.4302889e-26 | D28: =D17 -> g/(g solid year) | K28: 3.0160293 | L28: 3 | M28: He(g)
B29: =B28 -> = | C29: =C28/K47 -> 1.559833e-27 | D29: =D18 -> mol/(g solid year) | K29: 21.991385 | L29: 22 | M29: Ne(g)
B30: =B29 -> = | C30: =C29*$M$51*1000 -> 4.1335575e-24 | D30: =D19 -> mol/(dm^3 solid year) | K30: 35.967545 | L30: 36 | M30: Ar(g)
B31: =B30 -> = | C31: =C30/(365*86400) -> 1.3107425e-31 | D31: =D20 -> mol/(dm^3 s) | K31: 37.962732 | L31: 38 | M31: Ar(g)
B32: MIN3P hand calculation | K32: 81.913483 | L32: 82 | M32: Kr(g)
B33: r_22Ne= | C33: ='Ne-handCalc'!F14 -> 1.4238252e-31 | K33: 82.914127 | L33: 83 | M33: Kr(g)
B34: error [%] = | C34: =(C33-C31)/C33*100 -> 7.942176 | D34: % | K34: 85.910611 | L34: 86 | M34: Kr(g)
K35: 128.90478 | L35: 129 | M35: Xe(g)
K36: 133.90539 | L36: 134 | M36: Xe(g)
K37: 135.90721 | L37: 136 | M37: Xe(g)
K38: 131.90416 | L38: 132 | M38: Xe(g) | T38: 20Ne = (6.39[U]+0.770[Th])(0.0226[O]+0.0022[Na])*1e-22
K39: 4.0026033 | L39: 4 | M39: He(g) | Q39: 6.39*0.0226= | R39: =6.39*0.0226 -> 0.144414 | T39: ={(6.39*0.0226[U] +0.770*0.0226[Th])[O] +(6.39*0.0022[U] +0.770*0.0022[Th])[Na] }*1e-22
K40: 19.99244 | L40: 20 | M40: Ne(g) | Q40: 0.770*0.0226 = | R40: =0.77*0.0226 -> 0.017402 | T40: = {(6.39*0.0226[U] +0.770*0.0226[Th])[O] +(6.39*0.0022[U] +0.770*0.0022[Th])[Na] }*1e-22
K41: 39.962383 | L41: 40 | M41: Ar(g) | Q41: 6.39*0.0022 = | R41: =6.39*0.0022 -> 0.014058 | T41: ={(0.144[U] +0.0174[Th])[O] +(0.0141[U] +0.00169[Th])[Na] }*1e-22
...

Sheet Ar-handCalculation-BB
B1: Verification calculation directly based on B&B (2002) in order to verify the unit coversion.
B3: 36Ar production rate:
B5: r_36Ar = | C5: P_th*N*R*F35Cl | G5: p_th = | H5: 0.8 | I5: - | O5: 1 ppm = | P5: 1 | Q5: mg/kg solid = | R5: 0.001 | S5: g/kg solid
B6: = | C6: =H5*H6*H7*H8 -> 0.19074299 | D6: atoms/(g yr) | G6: N = | H6: ='neutronProduction-BB'!E32+'neutronProduction-BB'!E39+'neutronProduction-BB'!E12+'neutronProduction-BB'!E17 -> 11.204219 | I6: ='neutronProduction-BB'!H32 -> # of nutrons/(g solid year) | J6: ='neutronProduction-BB'!E47 -> 1.5631764e-27 | K6: ='neutronProduction-BB'!H47 -> mol of nutrons/(dm3 s) | M6: neutron density | O6: Rock density ρ_s = | Q6: 2.65 | R6: kg solid / dm3 solid
B7: = | C7: =C6/'neutronProduction-BB'!L30 -> 3.16691e-25 | D7: mol/(g yr) | G7: F35Cl = | H7: =H13 -> 0.022400278 | I7: -
B8: = | C8: =C7*$R$5*$Q$6/0.000001 -> 8.3923115e-22 | D8: ='Ne-handCalculation-BB'!D30 -> mol/(dm^3 solid year) | G8: R= | H8: 0.95
B9: = | C9: =C8/(365*86400) -> 2.6611845e-29 | D9: ='Ne-handCalculation-BB'!D31 -> mol/(dm^3 s) | H9: rel. abundance | I9: thermal neutron capture cross section [barns]
G10: 35Cl | H10: 0.7577 | I10: 43
B11: MIN3P hand calculation | G11: 37Cl | H11: 0.2423 | I11: 0.43
B12: r_36Ar= | C12: ='Ar-HandCalc'!K4 -> 2.6577538e-29 | G12: F_Cl= | H12: =0.00022/0.00979 -> 0.02247191 | J12: =I10/(I10+I11) -> 0.99009901 | K12: =J12*H10 -> 0.75019802
B13: error [%] = | C13: =(C12-C9)/C12*100 -> -0.12908453 | D13: % | G13: F35Cl = | H13: =H10*I10/(H10*I10+H11*I11)*H12 -> 0.022400278 | J13: =I11/(I10+I11) -> 0.0099009901 | K13: =J13*H11 -> 0.0023990099
G14: F37Cl = | H14: =H11*I11/(H10*I10+H11*I11)*H12 -> 7.1632404e-05 | J14: =J12+J13 -> 1 | K14: =K12+K13 -> 0.75259703
H15: =H13+H14 -> 0.02247191 | J15: =H10+H11 -> 1
J17: =H10*I10/(H10*I10+H11*I11) -> 0.99681236
J18: =H11*I11/(H10*I10+H11*I11) -> 0.003187642
J19: =J17+J18 -> 1
B25: 38Ar production rate:
A27: path 1 | B27: r_38Ar_1 = | C27: P_th*N*R*F37Cl
B28: = | C28: =H5*H6*H14*H8 -> 0.00060996471 | D28: atoms/(g yr)
B29: = | C29: =C28/'neutronProduction-BB'!L30 -> 1.0127257e-27 | D29: mol/(g yr)
B30: = | C30: =C29*$R$5*$Q$6/0.000001 -> 2.6837232e-24 | D30: =D8 -> mol/(dm^3 solid year)
B31: = | C31: =C30/(365*86400) -> 8.5100304e-32 | D31: =D9 -> mol/(dm^3 s)
A33: path 2 | B33: r_38Ar_2 = | C33: {[Cl]*(0.76*[U]+0.104*[Th])}*1e-25
B34: = | C34: =(J45*(0.76*H41+0.104*J39)*1E-25) -> 7.518656e-23 | D34: cm^3 STP/(g yr)
B35: = | C35: =C34*$J$48 -> 1.3383208e-25 | D35: ='Ne-handCalculation-BB'!D28 -> g/(g solid year)
B36: = | C36: =C35/H53 -> 3.5253542e-27 | D36: ='Ne-handCalculation-BB'!D29 -> mol/(g solid year) | H36: RE_j^s
B37: = | C37: =C36*$K$55*$J$56/0.000001 -> 9.3421886e-24 | D37: ='Ne-handCalculation-BB'!D30 -> mol/(dm^3 solid year) | H37: Concentrations in ppm
B38: = | C38: =C37/(365*86400) -> 2.9623886e-31 | D38: ='Ne-handCalculation-BB'!D31 -> mol/(dm^3 s) | H38: U235 | I38: U238 | J38: Th232
H39: ='Ar-HandCalc'!C10 -> 0.02 | I39: ='Ar-HandCalc'!D10 -> 2.78 | J39: ='Ar-HandCalc'!E10 -> 10.7
A40: total | B40: r_38Ar= | C40: =C38+C31 -> 3.8133916e-31 | D40: =D38 -> mol/(dm^3 s) | H40: U = U235+U238
H41: =H39+I39 -> 2.8
B44: MIN3P hand calculation | H44: ='Ar-HandCalc'!I19 -> weight fraction [kg E/(kg solid)] | I44: ='Ar-HandCalc'!J19 -> 0 | J44: E_i^s [ppm]
B45: r_38Ar= | C45: ='Ar-HandCalc'!K8 -> 3.7039837e-31 | H45: ='Ar-HandCalc'!I20 -> 0.000232 | I45: ='Ar-HandCalc'!J20 -> cl' | J45: =H45*1000000 -> 232
B46: error [%] = | C46: =(C45-C40)/C45*100 -> -2.9537918 | D46: %
H47: Density of Ar at STP
H48: 1.78 | I48: g/L = | J48: =H48/1000 -> 0.00178 | K48: g/cm^3
H49: molar mass [u]
H50: 3.0160293 | I50: 3 | J50: He(g)
H51: 21.991385 | I51: 22 | J51: Ne(g)
H52: 35.967545 | I52: 36 | J52: Ar(g)
...

Sheet KrXe-handCalculation-BB
C4: 136Xe production rate:
O5: 1 ppm = | P5: 1 | Q5: mg/kg solid = | R5: 0.001 | S5: g/kg solid
B6: path 1 | C6: r_136Xe_tnc = | D6: P_th*N*F235U*136Y | O6: Rock density ρ_s = | Q6: 2.65 | R6: kg solid / dm3 solid
C7: = | D7: =J7*J8*J9*J10 -> 2.9796218e-06 | E7: atoms/(g yr) | I7: p_th= | J7: 0.8 | K7: -
C8: = | D8: =D7/'neutronProduction-BB'!L30 -> 4.9470726e-30 | E8: mol/(g yr) | I8: N= | J8: ='neutronProduction-BB'!E12+'neutronProduction-BB'!E17+'neutronProduction-BB'!E32+'neutronProduction-BB'!E39 -> 11.204219 | K8: neutrons/(g solid yr)
C9: = | D9: =D8*$R$5*$Q$6/0.000001 -> 1.3109742e-26 | E9: ='Ar-handCalculation-BB'!D8 -> mol/(dm^3 solid year) | I9: F235U= | J9: =0.0000000503/0.00979 -> 5.1378958e-06 | K9: (Table 1
C10: = | D10: =D9/(365*86400) -> 4.1570721e-34 | E10: ='Ar-handCalculation-BB'!D9 -> mol/(dm^3 s) | I10: 136Ynf_235U= | J10: 0.0647 | K10: (Table 7 in B&B)
B12: path 2 | C12: r_136Xe_sf = | D12: (N_A/A_238U)*1e-6*[238U]*(136Y*λsf/λα)
C13: = | D13: =(J14/J15)*0.000001*J23*(L16/1) -> 0.038108921 | E13: atom/(g soild yr)
C14: = | D14: =D13/J14 -> 6.3272324e-26 | E14: =E8 -> mol/(g yr) | I14: N_A = | J14: 6.023e+23 | K14: Avogadro's number
C15: = | D15: =D14*$R$5*$Q$6/0.000001 -> 1.6767166e-22 | E15: =E9 -> mol/(dm^3 solid year) | I15: A_238U = | J15: 238.051 | K15: g/mol | N15: 136Y= | O15: 0.063
C16: = | D16: =D15/(365*86400) -> 5.3168334e-30 | E16: =E10 -> mol/(dm^3 s) | I16: 136Y*λsf = | J16: 6.83e-18 | K16: 1/yr | L16: =O16*O15 -> 5.418e-18 | M16: 1/yr | N16: λsf= | O16: 8.6e-17 | P16: 1/yr
I17: λα= | J17: 1.55e-10 | K17: 1/yr | L17: (Steiger and Jaeger 1977)
I18: X238[U] = [238U]
B19: total | C19: r_136Xe= | D19: =D16+D10 -> 5.3172491e-30 | E19: =E17 -> 0
I20: RE_j^s
I21: Concentrations in ppm
I22: U235 | J22: U238 | K22: Th232
C23: MIN3P hand calculation | I23: ='Ar-HandCalc'!C4 -> 0.02 | J23: ='Ar-HandCalc'!D4 -> 2.78 | K23: ='Ar-HandCalc'!E4 -> 10.7
C24: r_136Xe= | D24: ='KrXe-HandCalc'!H11 -> 5.2656534e-30 | I24: U = U235+U238
C25: error [%] = | D25: =(D24-D19)/D24*100 -> -0.97985401 | E25: % | I25: =I23+J23 -> 2.8
C27: Scaling factor | D27: YsfB&B [-] | E27: YtncB&B [-] | F27: RsfB&B | G27: RtncB&B | H27: RxB&B | I27: Ysf [-] | J27: Ytnc [-] | K27: Rsf | L27: Rtnc | M27: R_tot | N27: Err_sf [%] | O27: Err_tnc [%] | P27: Err_tot [%]
C28: 83Kr/86Kr | D28: 0.048 | E28: 0.27 | F28: =$F$30*D28 -> 3.1901e-32 | G28: =$G$30*E28 -> 3.5407238e-35 | H28: =F28+G28 -> 3.1936408e-32 | I28: =I30*D28 -> 0.000378 | J28: =J30*E28 -> 0.0055107256 | K28: ='KrXe-HandCalc'!F4 -> 3.1591429e-32 | L28: ='KrXe-HandCalc'!G4 -> 3.5356936e-35 | M28: =K28+L28 -> 3.1626786e-32 | N28: =(K28-F28)/K28*100 -> -0.9799211 | O28: =(L28-G28)/L28*100 -> -0.14226944 | P28: =(M28-H28)/M28*100 -> -0.97898465
C29: 84Kr/86Kr | D29: 0.159 | E29: 0.5 | F29: =$F$30*D29 -> 1.0567206e-31 | G29: =$G$30*E29 -> 6.556896e-35 | H29: =F29+G29 -> 1.0573763e-31 | I29: =I30*D29 -> 0.001252125 | J29: =J30*E29 -> 0.010205047 | K29: ='KrXe-HandCalc'!F5 -> 1.0446901e-31 | L29: ='KrXe-HandCalc'!G5 -> 6.5452042e-35 | M29: =K29+L29 -> 1.0453446e-31 | N29: =(K29-F29)/K29*100 -> -1.151587 | O29: =(L29-G29)/L29*100 -> -0.17863192 | P29: =(M29-H29)/M29*100 -> -1.1509778
C30: 136Xe/86Kr | D30: 8 | E30: 3.17 | F30: =F35/D30 -> 6.6460418e-31 | G30: =G35/E30 -> 1.3113792e-34 | H30: =F30+G30 -> 6.6473531e-31 | I30: =$I$35/D30 -> 0.007875 | J30: =$J$35/E30 -> 0.020410095 | K30: ='KrXe-HandCalc'!F6 -> 6.5857266e-31 | L30: ='KrXe-HandCalc'!G6 -> 1.3090408e-34 | M30: =K30+L30 -> 6.5870356e-31 | N30: =(K30-F30)/K30*100 -> -0.91584754 | O30: =(L30-G30)/L30*100 -> -0.17863192 | P30: =(M30-H30)/M30*100 -> -0.91570104
C31: 129Xe/136Xe | D31: 0.002 | E31: 0.15 | F31: =$F$35*D31 -> 1.0633667e-32 | G31: =$G$35*E31 -> 6.2356081e-35 | H31: =F31+G31 -> 1.0696023e-32 | I31: =$I$35*D31 -> 0.000126 | J31: =$J$35*E31 -> 0.009705 | K31: ='KrXe-HandCalc'!F7 -> 1.0530476e-32 | L31: ='KrXe-HandCalc'!G7 -> 6.2307777e-35 | M31: =K31+L31 -> 1.0592784e-32 | N31: =(K31-F31)/K31*100 -> -0.9799211 | O31: =(L31-G31)/L31*100 -> -0.077524756 | P31: =(M31-H31)/M31*100 -> -0.97461312
C32: 131Xe/136Xe | D32: 0.076 | E32: 0.453 | F32: =$F$35*D32 -> 4.0407934e-31 | G32: =$G$35*E32 -> 1.8831536e-34 | H32: =F32+G32 -> 4.0426765e-31 | I32: =$I$35*D32 -> 0.004788 | J32: =$J$35*E32 -> 0.0293091 | K32: ='KrXe-HandCalc'!F8 -> 4.0032526e-31 | L32: ='KrXe-HandCalc'!G8 -> 1.880142e-34 | M32: =K32+L32 -> 4.0051327e-31 | N32: =(K32-F32)/K32*100 -> -0.93775829 | O32: =(L32-G32)/L32*100 -> -0.16018264 | P32: =(M32-H32)/M32*100 -> -0.93739327
C33: 132Xe/136Xe | D33: 0.595 | E33: 0.677 | F33: =$F$35*D33 -> 3.1635159e-30 | G33: =$G$35*E33 -> 2.8143378e-34 | H33: =F33+G33 -> 3.1637973e-30 | I33: =$I$35*D33 -> 0.037485 | J33: =$J$35*E33 -> 0.0438019 | K33: ='KrXe-HandCalc'!F9 -> 3.1340704e-30 | L33: ='KrXe-HandCalc'!G9 -> 2.8105877e-34 | M33: =K33+L33 -> 3.1343514e-30 | N33: =(K33-F33)/K33*100 -> -0.93952913 | O33: =(L33-G33)/L33*100 -> -0.13342803 | P33: =(M33-H33)/M33*100 -> -0.93945685
C34: 134Xe/136Xe | D34: 0.832 | E34: 1.25 | F34: =$F$35*D34 -> 4.4236054e-30 | G34: =$G$35*E34 -> 5.1963401e-34 | H34: =F34+G34 -> 4.424125e-30 | I34: =$I$35*D34 -> 0.052416 | J34: =$J$35*E34 -> 0.080875 | K34: ='KrXe-HandCalc'!F10 -> 4.379341e-30 | L34: ='KrXe-HandCalc'!G10 -> 5.1912453e-34 | M34: =K34+L34 -> 4.3798601e-30 | N34: =(K34-F34)/K34*100 -> -1.0107547 | O34: =(L34-G34)/L34*100 -> -0.098142293 | P34: =(M34-H34)/M34*100 -> -1.0106465
C35: 136Xe | D35: 1 | E35: 1 | F35: =D16 -> 5.3168334e-30 | G35: =D10 -> 4.1570721e-34 | H35: =F35+G35 -> 5.3172491e-30 | I35: 0.063 | J35: 0.0647 | K35: ='KrXe-HandCalc'!F11 -> 5.2652382e-30 | L35: ='KrXe-HandCalc'!G11 -> 4.1517128e-34 | M35: =K35+L35 -> 5.2656534e-30 | N35: =(K35-F35)/K35*100 -> -0.9799211 | O35: =(L35-G35)/L35*100 -> -0.12908453 | P35: =(M35-H35)/M35*100 -> -0.97985401
C47: Table 7: Yield factors for ingrowth of Kr and Xe noble gas isotopes related to spontaneous fission of 238U and neutron capture by 235U (derived from Ballentine and Burnard, 2002)
C48: Noble gas isotope | D48: Spontaneous fission of 238U: Yield factor | E48: Neutron capture by 235U: Yield factor
D49: and | E49: and
D50: [-] | E50: [-]
D51: Derived from Table 7 in Ballentine and Burnard (2002), based on ratios from Wetherill (1953) | E51: Derived from Table 7 in Ballentine and Burnard (2002), based on ratios from Farrar and Tomlinson (1962)
C52: 83Kr | D52: 0.0004 | E52: 0.0087
C53: 84Kr | D53: 0.0013 | E53: 0.0102
C54: 86Kr | D54: 0.0079 | E54: 0.0204
C55: 129Xe | D55: 0.0001 | E55: 0.0097
C56: 131Xe | D56: 0.0048 | E56: 0.0293
...
